model
size = 19 19 21
scale = 0.05
origin = -y
material lighting = flat, roughness = 0, emissive = #12D1A0 0.5
  colors =  T(181):#12D1A0 
material lighting = flat, roughness = 0, emissive = #FFFF33 0.5
  colors = X(5):#FFFF33
material lighting = flat
  colors = B(248):#B6CAD7 C(138):#3B3A3A D(225):#110000 E(52):#EBAE75 F(147):#33FF99 G(145):#33FFFF H(211):#0000FF I(146):#33FFCC J(25):#FF33FF K(255):#111111 L(67):#CC00FF M(236):#0A5EF2 N(218):#FF0000 O(246):#EEEEEE P(251):#92A4AD Q(217):#C83C3C
material lighting = flat
  colors = R(216):#EE0000
material lighting = flat
  colors = S(233):#004400 U(229):#00AA00 V(231):#007700 W(32):#B95A73 Y(6):#FFFF00
voxels =
------------------- ------------------- ---------C--------- ------------------- ------------------- ------------------- ------------------- ------------------- ------------------- ------------------- ------------------- ------------------- ------------------- ------------------- -------OOOOO------- ------------------- ------------------- ------------------- ------------------- 
------------------- ------------------- --------CCC-------- --------CCC-------- --------CCC-------- --------CCC-------- --------CCC-------- --------CCC-------- ---------C--------- ------------------- ------------------- ------------------- ------------------- ------------------- ------OOOOOOO------ ------------------- ------------------- ------------------- ------------------- 
------------------- ------------------- ---------C--------- --------CCC-------- --------CCC-------- --------CCC-------- --------CCC-------- -------CCCCC------- -------CCCCC------- -------CCCCC------- -------CCCCC------- -------CCCCC------- -------CCCCC------- -------CCCCC------- -----OOOOOOOOO----- --------YYY-------- --------OOO-------- --------OOO-------- ---------O--------- 
------------------- ------------------- ------------------- ---------C--------- --------CCC-------- --------CCC-------- -------CCCCC------- -------CCCCC------- ------CCCCCCC------ ------CCCCCCC------ ------CCCCCCC------ ------CCCCCCC------ ------CCCCCCC------ ------CCCCCCC------ ----OOOOOOOOOOO---- -------YYYYY------- -------OOOOO------- -------OOOOO------- -------OOOOO------- 
------------------- ------------------- ------------------- ------------------- ------------------- -------CCCCC------- -------CCCCC------- ------CCCCCCC------ -----CCCCCCCCC----- -----CCCCCCCCC----- -----CCCCCCCCC----- -----CCCCCCCCC----- -----CCCCCCCCC----- -----CCCCCCCCC----- ---OOOOOOOOOOOOO--- ------YYYYYYY------ ------OOOOOOO------ ------OOOOOOO------ ------OO---OO------ 
------------------- ------------------- ------------------- ------------------- --------CCC-------- -------CCCCC------- ------CCCCCCC------ -----CCCCCCCCC----- -----CCCCCCCCC----- -----CCCCCCCCC----- -----CCCCCCCCC----- -----CCCCCCCCC----- -----CCCCCCCCC----- -----CCCCCCCCC----- ---OOOOOCCCOOOOO--- -----YYYYYYYYY----- -----OOOOOOOOO----- -----OOOOOOOOO----- ------O-OOO-O------ 
--------VSV-------- --------SVU-------- --------VSV-------- --------CCC-------- -------CCCCC------- ------CCCCCCC------ -----CCCCCCCCC----- -----CCCCCCCCC----- -----CCCCCCCCC----- ----XCCCCCCCCCX---- ----ECCCCCCCCEE---- ----TCCCCCCCCCT---- -----CCCCCCCCC----- -----CCCCCCCJC----- ---OOOOOCCCOOOOO--- -----YYYYYYYYY----- -----OOOOOOOOO----- -----OOOOOOOOO----- ------O-OOO-O------ 
-------SUUUS------- -------VMMMV------- -------UMMMS------- -------CCCCC------- ------CCCCCCC------ -----CCCCCCCCC----- -----CCCCCCCCC----- -----CCCCCCCCC----- -----CCCCCCCCC----- -----CCCCCCCCC----- -----CCCCCCCCC----- ----TCCCCCCCCCT---- -----CCCCCCCCC----- -----CCCCCCCHC----- ---OOOOOCCCOOOOO--- -----YYYYYYYYY----- -----OOOOOOOOO----- -----OOOOOOOOO----- ------O-OOO-O------ 
-------VUUUS------- -------UMMMU------- -------SMMMV------- -------CCCCC------- ------CCCCCCC------ -----CCCCCCCCC----- -----CCCCCCCCC----- -----CCCCCCCCC----- -----CCCCCCCCC----- -----CCCCCCCCC----- -----CCCCCCCCC----- ----TCCCCCCCCCT---- -----CCCCCCCCC----- -----CCCCCCCHC----- ---OOOOOCCCOOOOO--- -----YYYYYYYYY----- -----OOOOOOOOO----- -----OOOOOOOOO----- ------O-OOO-O------ 
-------SUUUV------- -------VMMMV------- --------VCV-------- --------CCC-------- ------CCCCCCC------ -----CCCCCCCCC----- -----CCCCCCCCC----- -----CCCCCCCCC----- -----CCCCCCCCC----- -----CCCCCCCCC----- -----CCCCCCCCC----- ----TCCCCCCCCCT---- -----CCCCCCCCC----- -----CCCCCCCHC----- ---OOOOOCCCOOOOO--- -----YYYYYYYYY----- -----OOOOOOOOO----- -----OOOOOOOOO----- ------OO-O-OO------ 
-------VUUUU------- -------SMCMS------- --------CCC-------- ------------------- ------CCCCCCC------ ------CCCCCCC------ -----CCCCCCCCC----- -----CCCCCCCCC----- -----CCCCCCCCC----- ----CCCCCCCCCCC---- -----CCCCCCCCC----- ----TCCCCCCCCCT---- -----CCCCCCCCC----- -----CCCCCCCHC----- ---OOOOOCCCOOOOO--- -----YYYYYYYYY----- -----OOOOOOOOO----- ------OOOOOOO------ -------OO-OO------- 
-------SVVSV------- -------VUCVU------- ------------------- ------------------- -------CCCCC------- ------CCCCCCC------ ------CCCCCCC------ ------CCCCCCC------ ------CCCCCCC------ ----CCCCCCCCCCC---- ------CCCCCCC------ ----T-CCCCCCC-T---- ------CCCCCCC------ ------CCCCCCC------ ---OOOOOOOOOOOOO--- ------YYYYYYY------ ------OOOOOOO------ -------OOOOO------- --------OOO-------- 
------------------- ------------------- ------------------- ------------------- --------EEE-------- -------EEEEE------- ------EEEEEEE------ ------EECCCEE------ ------CECCCEC------ ------ECCCCCE------ -----TECCCCCET----- -----TCCCCCCCT----- ------CCCCCCC------ ------CCCCCCC------ ----OOOOOOOOOOO---- -------YYYYY------- -------OOOOO------- --------OOO-------- ---------O--------- 
------------------- ------------------- ------------------- ------------------- --------EEE-------- -------EEEEE------- -------EWWEE------- -------EEEEE------- -------EEEEE------- -------EEEEE------- ------TEAEAET------ ------TEEEEET------ -------CEEEC------- -------CCCCC------- -----OOOOOOOOO----- --------YYY-------- --------OOO-------- ---------O--------- ------------------- 
------------------- ------------------- ------------------- ------------------- ------------------- ------------------- ------------------- ------------------- ------------------- ------------------- -------TTTTT------- -------TTTTT------- -------C---C------- --------CCC-------- ------OOOOOOO------ ------------------- ------------------- ------------------- ------------------- 
------------------- ------------------- ------------------- ------------------- ------------------- ------------------- ------------------- ------------------- ------------------- ------------------- ------------------- ------------------- ------------------- ------------------- -------OOOOO------- ------------------- ------------------- ------------------- ------------------- 
------------------- ------------------- ------------------- ------------------- ------------------- ------------------- ------------------- ------------------- ------------------- ------------------- ------------------- ------------------- ------------------- ------------------- ------------------- ------------------- ------------------- ------------------- ------------------- 
------------------- RR--RR--RRR-R---RR- ------------------- ------------------- ------------------- ------------------- ------------------- ------------------- ------------------- ------------------- ------------------- ------------------- ------------------- ------------------- ------------------- ------------------- ------------------- ------------------- ------------------- 
------------------- RRR-RRR--R--R---RRR ------------------- ------------------- ------------------- ------------------- ------------------- ------------------- ------------------- ------------------- ------------------- ------------------- ------------------- ------------------- ------------------- ------------------- ------------------- ------------------- ------------------- 
------------------- R-R-R-R--R--R---R-R ------------------- ------------------- ------------------- ------------------- ------------------- ------------------- ------------------- ------------------- ------------------- ------------------- ------------------- ------------------- ------------------- ------------------- ------------------- ------------------- ------------------- 
------------------- RRR-RRR--R--RRR-RRR ------------------- ------------------- ------------------- ------------------- ------------------- ------------------- ------------------- ------------------- ------------------- ------------------- ------------------- ------------------- ------------------- ------------------- ------------------- ------------------- ------------------- 
