model
size = 13 19 22
scale = 0.05
rotation = 0 -45 0
origin = -y
material lighting = both, roughness = 0.2, metalness = 1, deform = 5 1, clamp = -x
  colors = A:#800
material lighting = flat, deform = 2 1, scatter = 0.2
  colors = B:#080
material lighting = both, roughness = 0, metalness = 1, opacity = 0.7, deform = 10 1, clamp = y
  colors = C:#8CF
material lighting = flat,  emissive = #6E6971 0.5 , deform = 0.2 1, scatter = 0.1
  colors = K(249):#6E6971 
material lighting = flat, roughness = 0.1 
  colors = H(245):#000011
material lighting = flat
  colors = E(138):#442623 F(246):#EEEEEE G(52):#EAAE75 I(255):#111111 J(96):#5C3B27 L(6):#FABF38
voxels =
------------- ------------- ------------- ------------- ------------- ------------- ------------- ------------- ------------- ------------- ------------- ------------- ------------- ------------- ----FFFFF---- ------------- ------------- ------------- ------------- 
------------- ------------- ------------- ------------- ------------- ------------- ------------- ------------- ------------- ------------- ------------- ------------- ------------- ------------- ---FFFFFFF--- ------------- ------------- ------------- ------------- 
------------- ------------- ------------- ------------- ------------- ------------- ------------- ------------- -----EEE----- ----EEEEE---- ----EEEEE---- ----EEEEE---- ----EEEEE---- ----EEEEE---- --FFFFFFFFF-- -----LLL----- -----FFF----- -----FFF----- ------F------ 
------------- ------------- ------------- ------------- ------------- ------------- ------------- ----EEEEE---- ---EEEEEEE--- ---EEEEEEE--- ---EEEEEEE--- ---EEEEEEE--- ---EEEEEEE--- ---EEEEEEE--- -FFFFFFFFFFF- ----LLLLL---- ----FFFFF---- ----FFFFF---- ----FFFFF---- 
------------- ------------- ------------- ------------- ------------- ------------- ----EEEEE---- ---EEEEEEE--- --EEEEEEEEE-- --EEEEEEEEE-- --EEEEEEEEE-- --EEEEEEEEE-- --EEEEEEEEE-- --EEEEEEEEE-- FFFFFFFFFFFFF ---LLLLLLL--- ---FFFFFFF--- ---FFFFFFF--- ---FF---FF--- 
------------- ------------- ------------- ------------- ------------- ----EEEEE---- ---EEEEEEE--- --EEEEEEEEE-- --EEEEEEEEE-- --EEEEEEEEE-- --EEEEEEEEE-- --EEEEEEEEE-- --EEEEEEEEE-- --EEEEEEEEE-- FFFFFEEEFFFFF --LLLLLLLLL-- --FFFFFFFFF-- --FFFFFFFFF-- ---F-FFF-F--- 
-----FFF----- -----FFF----- -----FFF----- -----EEE----- ----EEEEE---- ---EEEEEEE--- --EEEEEEEEE-- --EEEEEEEEE-- --EEEEEEEEE-- --EEEEEEEEE-- -GEEEEEEEEEG- -HIEEEEEEEIH- --EEEEEEEEE-- --EEEEEEEEE-- FFFFFEEEFFFFF --LLLLLLLLL-- --FFFFFFFFF-- --FFFFFFFFF-- ---F-FFF-F--- 
----FFFFF---- ----FFFFF---- ----FFFFF---- ----EEEEE---- ---EEEEEEE--- --EEEEEEEEE-- --EEEEEEEEE-- --EEEEEEEEE-- --EEEEEEEEE-- --EEEEEEEEE-- --EEEEEEEEE-- -HIEEEEEEEIH- --EEEEEEEEE-- --EEEEEEEEE-- FFFFFEEEFFFFF --LLLLLLLLL-- --FFFFFFFFF-- --FFFFFFFFF-- ---F-FFF-F--- 
----FFFFF---- ----FFFFF---- ----FFFFF---- ----EEEEE---- ---EEEEEEE--- --EEEEEEEEE-- --EEEEEEEEE-- --EEEEEEEEE-- --EEEEEEEEE-- --EEEEEEEEE-- --EEEEEEEEE-- -HIEEEEEEEIH- --EEEEEEEEE-- --EEEEEEEEE-- FFFFFEEEFFFFF --LLLLLLLLL-- --FFFFFFFFF-- --FFFFFFFFF-- ---F-FFF-F--- 
-----FFF----- -----FFF----- -----FFF----- -----EEE----- ---EEEEEEE--- --EEEEEEEEE-- --EEEEEEEEE-- --EEEEEEEEE-- --EEEEEEEEE-- --EEEEEEEEE-- --EEEEEEEEE-- -HIEEEEEEEHH- --EEEEEEEEE-- --EEEEEEEEE-- FFFFFEEEFFFFF --LLLLLLLLL-- --FFFFFFFFF-- --FFFFFFFFF-- ---FF-F-FF--- 
------------- ------------- ------------- ------------- ---EEEEEEE--- ---EEEEEEE--- --EEEEEEEEE-- --EEEEEEEEE-- --EEEEEEEEE-- --EEEEEEEEE-- --EEEEEEEEE-- -HIEEEEEEEHH- --EEEEEEEEE-- --EEEEEEEEE-- FFFFFEEEFFFFF --LLLLLLLLL-- --FFFFFFFFF-- ---FFFFFFF--- ----FF-FF---- 
------------- ------------- ------------- ------------- ----EEEEE---- ---EEEEEEE--- ---EEEEEEE--- ---EEEEEEE--- ---EEEEEEE--- ---EEEEEEE--- ---EEEEEEE--- --HIEEEEEEH-- ---EEEEEEE--- ---EEEEEEE--- FFFFFFFFFFFFF ---LLLLLLL--- ---FFFFFFF--- ----FFFFF---- -----FFF----- 
------------- ------------- ------------- ------------- -----GGG----- ----GGGGG---- ---GGGGGGG--- ---GGEEEGG--- ---EGEEEGE--- ---GEEEEEG--- ---GEEEEEG--- --HGEEEEEGH-- ---EEEEEEE--- ---EEEEEEE--- -FFFFFFFFFFF- ----LLLLL---- ----FFFFF---- -----FFF----- ------F------ 
------------- ------------- ------------- ------------- -----GGG----- ----GGGGG---- ----GGGGG---- ----GGGGG---- ----GGGGG---- ----GGGGG---- ----GGGGG---- --H-GGGGG-H-- ----GGEGG---- ----EEEEE---- --FFFFFFFFF-- -----LLL----- -----FFF----- ------F------ ------------- 
------------- ------------- ------------- ------------- ------------- ------------- -------J----- ------------- ------------- ------------- ---HHH-HHH--- --HHHHHHHHH-- ------------- ------------- ---FFFFFFF--- ------------- ------------- ------------- ------------- 
------------- ------------- ------------- ------------- ------------- ------------- -------J----- ------------- ------------- ------------- ------------- ------------- ------------- ------------- ----FFFFF---- ------------- ------------- ------------- ------------- 
------------- ------------- ------------- ------------- ------------- ------------- -------J----- ------------- ------------- ------------- ------------- ------------- ------------- ------------- ------------- ------------- ------------- ------------- ------------- 
------------- ------------- ------------- ------------- ------------- ------------- -------J----- ------------- ------------- ------------- ------------- ------------- ------------- ------------- ------------- ------------- ------------- ------------- ------------- 
------------- ------------- ------------- ------------- ------------- ------------- -------J----- -------J----- ------------- ------------- ------------- ------------- ------------- ------------- ------------- ------------- ------------- ------------- ------------- 
------------- ------------- ------------- ------------- ------------- ------------- -------J----- -------J----- ------------- -------K----- ------------- ------------- ------------- ------------- -------K----- -------K----- ------------- ------------- ------------- 
------------- ------------- ------------- ------------- ------------- ------------- ------------- ------------- ------------- ------------- ------------- -------K----- -------K----- ------------- ------KKK---- ------KKK---- -------K----- ------------- ------------- 
------------- ------------- ------------- ------------- ------------- ------------- ------------- ------------- ------------- ------------- ------------- ------------- ------------- ------------- -------K----- -------K----- ------------- ------------- ------------- 
