model
size = 23 18 19
scale = 0.05
origin = -y
material lighting = flat
  colors = A(248):#B6CAD7
material lighting = flat
  colors = B(138):#825039 C(225):#110000 D(52):#EBAE75 E(147):#33FF99 F(145):#33FFFF G(211):#0000FF H(146):#33FFCC I(25):#FF33FF J(255):#111111 K(245):#222 L(67):#CC00FF M(216):#EE0000 N(236):#0A5EF2 O(218):#FF0000 P(246):#EEEEEE
material lighting = flat
  colors = Q(251):#92A4AD R(217):#C83C3C
voxels =
----------------------- ----------------------- ----------------------- ----------------------- ----------------------- ----------------------- ----------------------- ----------------------- ----------QQQ---------- ---------QQQQQ--------- ---------QQQQQ--------- ---------QQQQQ--------- ---------QQQQQ--------- ---------RRRRR--------- ---------RRRRR--------- ----------RRR---------- ----------------------- ----------------------- 
----------------------- ----------------------- ----------------------- ----------------------- ----------------------- ----------------------- ----------------------- ---------QQQQQ--------- --------QQQQQQQ-------- --------QQQQQQQ-------- --------QQQQQQQ-------- --------QQQQQQQ-------- --------QQQQQQQ-------- --------RRRRRRR-------- --------RRRRRRR-------- ---------RRRRR--------- ----------RRR---------- ----------------------- 
----------------------- ----------------------- ----------------------- ----------------------- ----------------------- ----------------------- ---------QQQQQ--------- --------QQQQQQQ-------- -------QQQBBBQQQ------- -------QQQBBBQQQ------- -------QBBBBBQQQ------- -------QBBBBBQQQ------- -------QQBBBBQQQ------- -------RRRRRRRRR------- -------RRRRRRRRR------- --------RRRRRRR-------- ---------RR-RR--------- -----------R----------- 
----------------------- ----------------------- ----------------------- ----------------------- ----------------------- ---------QQQQQ--------- --------QQQQQQQ-------- -------QQQQQQQQQ------- -------QQQBBBQQQ------- -------QQQBBBQQQ------- -------QBBBBBQQQ------- -------QBBBBBQQQ------- -------QQBBBBQQQ------- -------RRRRRRRRR------- -------RRRRRRRRR------- -------RRRRRRRRR------- --------RRR-RRR-------- ----------RRR---------- 
----------RRR---------- ----------RRR---------- ----------RRR---------- ----------QQQ---------- ---------QQQQQ--------- --------QQQQQQQ-------- -------QQQQQQQQQ------- -------QQQQQQQQQ------- -------QQQBBBQQQ------- -------QQQBBBQQQ------- ------ADBBBBBQQQA------ ------KJBBBBBQQQK------ -------QQBBBBQQQ------- -------RRRRRRRRR------- -------RRRRRRRRR------- -------RRRRRRRRR------- --------RRR-RRR-------- ----------RRR---------- 
---------RRRRR--------- ---------RRRRR--------- ---------RRRRR--------- ---------QQQQQ--------- --------QQQQQQQ-------- -------QQQQQQQQQ------- -------QQQQQQQQQ------- -------QQQQQQQQQ------- -------QQQBBBQQQ------- -------QQQBBBQQQ------- -------QBBBBBQQQ------- ------KJBBBBBQQQK------ -------QQBBBBQQQ------- -------RRRRRRRRR------- -------RRRRRRRRR------- -------RRRRRRRRR------- --------RRR-RRR-------- ----------RRR---------- 
---------RRRRR--------- ---------RRRRR--------- ---------RRRRR--------- ---------QQQQQ--------- --------QQQQQQQ-------- -------QQQQQQQQQ------- -------QQQQQQQQQ------- -------QQQQQQQQQ------- -------QBBBBBBQQ------- -------QBBBBBBQQ------- -------QBBBBBBQQ------- ------KJBBBBBBQQK------ -------QQBBBBBQQ------- -------RRRRRRRRR------- -------RRRRRRRRR------- -------RRRRRRRRR------- --------RRRRRRR-------- ----------RRR---------- 
----------RRR---------- ----------RRR---------- ----------RRR---------- ----------QQQ---------- --------QQQQQQQ-------- -------QQQBBBQQQ------- -------QQQBBBQQQ------- -------QQQBBBQQQ------- -------QBBBBBBQQ------- -------QBBBBBBQQ------- -------QBBBBBBQQ------- ------KJBBBBBBQQK------ -------QQBBBBBQQ------- -------RRRRRRRRR------- -------RRRRRRRRR------- -------RRRRRRRRR------- --------RRRRRRR-------- ----------RRR---------- 
----------------------- ----------------------- ----------------------- ----------------------- --------QQQQQQQ-------- --------QQBBBQQ-------- -------QQQBBBQQQ------- -------QQQBBBQQQ------- -------QQBBBBBQQ------- -------QBBBBBBQQ------- -------QBBBBBBQQ------- ------KJBBBBBBQQK------ -------QQBBBBBQQ------- -------RRRRRRRRR------- -------RRRRRRRRR------- --------RRRRRRR-------- ---------RRRRR--------- ----------RRR---------- 
----------------------- ----------------------- ----------------------- ----------------------- ---------QQQQQ--------- --------QQBBBQQ-------- --------QQBBBQQ-------- --------QQBBBQQ-------- --------QBBBBBQ-------- --------QBBBBBQ-------- --------QBBBBBQ-------- -------KJBBBBBQK------- --------QBBBBBQ-------- -------RRRRRRRRR------- --------RRRRRRR-------- --------RRRRRRR-------- ---------RRRRR--------- -----------R----------- 
----------------------- ----------------------- ----------------------- ----------------------- ----------AAA---------- ---------AAAAA--------- --------AADADAA-------- --------ADABAAA-------- --------QDBBBDQ-------- --------ABBBBBA-------- --------ABBBBBA-------- -------KABBBBBDK------- --------QBBBBBQ-------- -------RRRRRRRRR------- --------RRRRRRR-------- ---------RRRRR--------- ----------RRR---------- ----------------------- 
----------------------- ----------------------- ----------------------- ----------------------- ----------AAA---------- ---------AAAAA--------- ----------A-A---------- ---------A-A-A--------- ---------AAAAA--------- ---------AAAAA--------- ---------ADADA--------- -------K-ADDDA-K------- ---------AAQAA--------- -------RRRRRRRRR------- ---------RRRRR--------- ----------RRR---------- ----------------------- ----------------------- 
----------------------- ----------------------- ----------------------- ----------------------- ----------------------- ----------------------- ----------------------- ----------------------- ----------------------- ----------------------- --------KKK-KKK-------- -------KKKKKKKKK------- ----------------------- -------RRRRRRRRR------- ----------------------- ----------------------- ----------------------- ----------------------- 
----------------------- ----------------------- ----------------------- ----------------------- ----------------------- ----------------------- ----------------------- ----------------------- ----------------------- ----------------------- ----------------------- ----------------------- ----------------------- --------RRRRRRR-------- ----------------------- ----------------------- ----------------------- ----------------------- 
----------------------- ----------------------- ----------------------- ----------------------- ----------------------- ----------------------- ----------------------- ----------------------- ----------------------- ----------------------- ----------------------- ----------------------- ----------------------- ---------RRRRR--------- ----------------------- ----------------------- ----------------------- ----------------------- 
----------------------- MMM-MM--MM--M---MM--MM- ----------------------- ----------------------- ----------------------- ----------------------- ----------------------- ----------------------- ----------------------- ----------------------- ----------------------- ----------------------- ----------------------- ----------RRR---------- ----------------------- ----------------------- ----------------------- ----------------------- 
----------------------- M---MMM-MMM-M---MMM-M-M ----------------------- ----------------------- ----------------------- ----------------------- ----------------------- ----------------------- ----------------------- ----------------------- ----------------------- ----------------------- ----------------------- ----------------------- ----------------------- ----------------------- ----------------------- ----------------------- 
----------------------- M---M---M---M---M---MM- ----------------------- ----------------------- ----------------------- ----------------------- ----------------------- ----------------------- ----------------------- ----------------------- ----------------------- ----------------------- ----------------------- ----------------------- ----------------------- ----------------------- ----------------------- ----------------------- 
----------------------- MMM-MMM-MMM-MMM-MMM-M-M ----------------------- ----------------------- ----------------------- ----------------------- ----------------------- ----------------------- ----------------------- ----------------------- ----------------------- ----------------------- ----------------------- ----------------------- ----------------------- ----------------------- ----------------------- ----------------------- 
